<?xml version="1.0"?>
<!-- Fanuc CRX-20iA/L - URDF with meshes for ManipulaPy -->
<!-- Payload: 20 kg, Reach: 1418 mm -->
<!-- Copyright (c) 2025 FANUC CORPORATION - Meshes licensed under Apache-2.0 -->
<robot name="crx20ia_l">
  
  <!-- Base Link -->
  <link name="base_link">
    <visual>
      <origin xyz="0 0 0" rpy="0 0 0"/>
      <geometry>
        <mesh filename="meshes/crx20ia_l/visual/base.dae"/>
      </geometry>
    </visual>
    <collision>
      <origin xyz="0 0 0" rpy="0 0 0"/>
      <geometry>
        <mesh filename="meshes/crx20ia_l/collision/base.stl" scale="0.001 0.001 0.001"/>
      </geometry>
    </collision>
    <inertial>
      <mass value="5.0"/>
      <origin xyz="0 0 0.05" rpy="0 0 0"/>
      <inertia ixx="0.01" ixy="0" ixz="0" iyy="0.01" iyz="0" izz="0.02"/>
    </inertial>
  </link>
  
  <!-- Link 1 -->
  <link name="link_1">
    <visual>
      <origin xyz="0 0 -0.245" rpy="0 0 0"/>
      <geometry>
        <mesh filename="meshes/crx20ia_l/visual/j1.dae"/>
      </geometry>
    </visual>
    <collision>
      <origin xyz="0 0 -0.245" rpy="0 0 0"/>
      <geometry>
        <mesh filename="meshes/crx20ia_l/collision/j1.stl" scale="0.001 0.001 0.001"/>
      </geometry>
    </collision>
    <inertial>
      <mass value="12.0"/>
      <origin xyz="0 0 0.1" rpy="0 0 0"/>
      <inertia ixx="0.05" ixy="0" ixz="0" iyy="0.05" iyz="0" izz="0.08"/>
    </inertial>
  </link>
  
  <!-- Link 2 -->
  <link name="link_2">
    <visual>
      <origin xyz="-0.0 0 -0.245" rpy="0 0 0"/>
      <geometry>
        <mesh filename="meshes/crx20ia_l/visual/j2.dae"/>
      </geometry>
    </visual>
    <collision>
      <origin xyz="-0.0 0 -0.245" rpy="0 0 0"/>
      <geometry>
        <mesh filename="meshes/crx20ia_l/collision/j2.stl" scale="0.001 0.001 0.001"/>
      </geometry>
    </collision>
    <inertial>
      <mass value="14.0"/>
      <origin xyz="0 0 0.355" rpy="0 0 0"/>
      <inertia ixx="0.5" ixy="0" ixz="0" iyy="0.5" iyz="0" izz="0.05"/>
    </inertial>
  </link>
  
  <!-- Link 3 -->
  <link name="link_3">
    <visual>
      <origin xyz="-0.0 0 -0.955" rpy="0 0 0"/>
      <geometry>
        <mesh filename="meshes/crx20ia_l/visual/j3.dae"/>
      </geometry>
    </visual>
    <collision>
      <origin xyz="-0.0 0 -0.955" rpy="0 0 0"/>
      <geometry>
        <mesh filename="meshes/crx20ia_l/collision/j3.stl" scale="0.001 0.001 0.001"/>
      </geometry>
    </collision>
    <inertial>
      <mass value="5.0"/>
      <origin xyz="0 0 0" rpy="0 0 0"/>
      <inertia ixx="0.01" ixy="0" ixz="0" iyy="0.01" iyz="0" izz="0.02"/>
    </inertial>
  </link>
  
  <!-- Link 4 -->
  <link name="link_4">
    <visual>
      <origin xyz="-0.0 0 -0.955" rpy="0 0 0"/>
      <geometry>
        <mesh filename="meshes/crx20ia_l/visual/j4.dae"/>
      </geometry>
    </visual>
    <collision>
      <origin xyz="-0.0 0 -0.955" rpy="0 0 0"/>
      <geometry>
        <mesh filename="meshes/crx20ia_l/collision/j4.stl" scale="0.001 0.001 0.001"/>
      </geometry>
    </collision>
    <inertial>
      <mass value="5.0"/>
      <origin xyz="0.27 0 0" rpy="0 0 0"/>
      <inertia ixx="0.01" ixy="0" ixz="0" iyy="0.08" iyz="0" izz="0.08"/>
    </inertial>
  </link>
  
  <!-- Link 5 -->
  <link name="link_5">
    <visual>
      <origin xyz="-0.54 0 -0.955" rpy="0 0 0"/>
      <geometry>
        <mesh filename="meshes/crx20ia_l/visual/j5.dae"/>
      </geometry>
    </visual>
    <collision>
      <origin xyz="-0.54 0 -0.955" rpy="0 0 0"/>
      <geometry>
        <mesh filename="meshes/crx20ia_l/collision/j5.stl" scale="0.001 0.001 0.001"/>
      </geometry>
    </collision>
    <inertial>
      <mass value="3.0"/>
      <origin xyz="0 -0.075 0" rpy="0 0 0"/>
      <inertia ixx="0.005" ixy="0" ixz="0" iyy="0.004" iyz="0" izz="0.006"/>
    </inertial>
  </link>
  
  <!-- Link 6 -->
  <link name="link_6">
    <visual>
      <origin xyz="-0.54 0.15 -0.955" rpy="0 0 0"/>
      <geometry>
        <mesh filename="meshes/crx20ia_l/visual/j6.dae"/>
      </geometry>
    </visual>
    <collision>
      <origin xyz="-0.54 0.15 -0.955" rpy="0 0 0"/>
      <geometry>
        <mesh filename="meshes/crx20ia_l/collision/j6.stl" scale="0.001 0.001 0.001"/>
      </geometry>
    </collision>
    <inertial>
      <mass value="1.5"/>
      <origin xyz="0.08 0 0" rpy="0 0 0"/>
      <inertia ixx="0.001" ixy="0" ixz="0" iyy="0.001" iyz="0" izz="0.001"/>
    </inertial>
  </link>
  
  <!-- Flange (end-effector mounting point) -->
  <link name="flange"/>
  
  <!-- Joint 1: Rotation about Z-axis -->
  <joint name="joint_1" type="revolute">
    <origin xyz="0 0 0.245" rpy="0 0 0"/>
    <parent link="base_link"/>
    <child link="link_1"/>
    <axis xyz="0 0 1"/>
    <limit lower="-3.316126" upper="3.316126" effort="600" velocity="1.745329"/>
  </joint>
  
  <!-- Joint 2: Rotation about Y-axis -->
  <joint name="joint_2" type="revolute">
    <origin xyz="0.0 0 0" rpy="0 0 0"/>
    <parent link="link_1"/>
    <child link="link_2"/>
    <axis xyz="0 1 0"/>
    <limit lower="-3.141593" upper="3.141593" effort="600" velocity="1.745329"/>
  </joint>
  
  <!-- Joint 3: Rotation about -Y-axis -->
  <joint name="joint_3" type="revolute">
    <origin xyz="0 0 0.71" rpy="0 0 0"/>
    <parent link="link_2"/>
    <child link="link_3"/>
    <axis xyz="0 -1 0"/>
    <limit lower="-1.239184" upper="4.310963" effort="300" velocity="2.617994"/>
  </joint>
  
  <!-- Joint 4: Rotation about -X-axis -->
  <joint name="joint_4" type="revolute">
    <origin xyz="0 0 0.0" rpy="0 0 0"/>
    <parent link="link_3"/>
    <child link="link_4"/>
    <axis xyz="-1 0 0"/>
    <limit lower="-3.316126" upper="3.316126" effort="100" velocity="2.617994"/>
  </joint>
  
  <!-- Joint 5: Rotation about -Y-axis -->
  <joint name="joint_5" type="revolute">
    <origin xyz="0.54 0 0" rpy="0 0 0"/>
    <parent link="link_4"/>
    <child link="link_5"/>
    <axis xyz="0 -1 0"/>
    <limit lower="-3.141593" upper="3.141593" effort="100" velocity="2.617994"/>
  </joint>
  
  <!-- Joint 6: Rotation about -X-axis -->
  <joint name="joint_6" type="revolute">
    <origin xyz="0 -0.15 0" rpy="0 0 0"/>
    <parent link="link_5"/>
    <child link="link_6"/>
    <axis xyz="-1 0 0"/>
    <limit lower="-3.926991" upper="3.926991" effort="100" velocity="2.617994"/>
  </joint>
  
  <!-- Flange joint (fixed) -->
  <joint name="joint_6_flange" type="fixed">
    <origin xyz="0.16 0 0" rpy="0 0 0"/>
    <parent link="link_6"/>
    <child link="flange"/>
  </joint>
  
</robot>
